2019-04-08 22:42:18,061 test_case_step.py 306 ERROR  [Errno 22] Invalid argument
2019-04-08 22:42:21,071 test_case.py 121 ERROR  执行用例测试步骤失败，正在进行第 1 次重试（第 1 步, 步骤ID: 1, 用例ID：2, 用例名称：ID2-N_获取时间和日期）
2019-04-08 22:42:22,162 test_case_step.py 306 ERROR  [Errno 22] Invalid argument
2019-04-08 22:42:22,167 test_case.py 131 ERROR  执行用例测试步骤运行失败（第 1 步, 步骤ID: 1， 用例ID：2, 用例名称：ID2-N_获取时间和日期）======================
2019-04-08 22:42:22,169 APIRunner.py 143 ERROR  用例（ID:2 名称：ID2-N_获取时间和日期）运行出错：步骤(第 1 步, 步骤ID: 1)运行失败:[Errno 22] Invalid argument
2019-04-08 22:42:22,180 logWebsocketConsumers.py 233 ERROR  调试运行失败：用例（ID:2 名称：ID2-N_获取时间和日期）运行出错：步骤(第 1 步, 步骤ID: 1)运行失败:[Errno 22] Invalid argument
2019-04-08 22:43:21,398 test_case_step.py 306 ERROR  [Errno 22] Invalid argument
2019-04-08 22:43:24,405 test_case.py 121 ERROR  执行用例测试步骤失败，正在进行第 1 次重试（第 1 步, 步骤ID: 1, 用例ID：2, 用例名称：ID2-N_获取时间和日期）
2019-04-08 22:43:25,507 test_case_step.py 306 ERROR  [Errno 22] Invalid argument
2019-04-08 22:43:25,512 test_case.py 131 ERROR  执行用例测试步骤运行失败（第 1 步, 步骤ID: 1， 用例ID：2, 用例名称：ID2-N_获取时间和日期）======================
2019-04-08 22:43:25,515 APIRunner.py 143 ERROR  用例（ID:2 名称：ID2-N_获取时间和日期）运行出错：步骤(第 1 步, 步骤ID: 1)运行失败:[Errno 22] Invalid argument
2019-04-08 22:43:25,525 logWebsocketConsumers.py 233 ERROR  调试运行失败：用例（ID:2 名称：ID2-N_获取时间和日期）运行出错：步骤(第 1 步, 步骤ID: 1)运行失败:[Errno 22] Invalid argument
2019-04-08 22:46:05,223 test_case_step.py 306 ERROR  [Errno 22] Invalid argument
2019-04-08 22:46:08,232 test_case.py 121 ERROR  执行用例测试步骤失败，正在进行第 1 次重试（第 1 步, 步骤ID: 1, 用例ID：2, 用例名称：ID2-N_获取时间和日期）
2019-04-08 22:46:09,423 test_case_step.py 306 ERROR  [Errno 22] Invalid argument
2019-04-08 22:46:09,433 test_case.py 131 ERROR  执行用例测试步骤运行失败（第 1 步, 步骤ID: 1， 用例ID：2, 用例名称：ID2-N_获取时间和日期）======================
2019-04-08 22:46:09,438 APIRunner.py 143 ERROR  用例（ID:2 名称：ID2-N_获取时间和日期）运行出错：步骤(第 1 步, 步骤ID: 1)运行失败:[Errno 22] Invalid argument
2019-04-08 22:46:09,451 logWebsocketConsumers.py 233 ERROR  调试运行失败：用例（ID:2 名称：ID2-N_获取时间和日期）运行出错：步骤(第 1 步, 步骤ID: 1)运行失败:[Errno 22] Invalid argument
2019-04-08 22:47:52,425 test_case_step.py 306 ERROR  [Errno 22] Invalid argument
2019-04-08 22:47:55,434 test_case.py 121 ERROR  执行用例测试步骤失败，正在进行第 1 次重试（第 1 步, 步骤ID: 1, 用例ID：2, 用例名称：ID2-N_获取时间和日期）
2019-04-08 22:47:56,670 test_case_step.py 306 ERROR  [Errno 22] Invalid argument
2019-04-08 22:47:56,677 test_case.py 131 ERROR  执行用例测试步骤运行失败（第 1 步, 步骤ID: 1， 用例ID：2, 用例名称：ID2-N_获取时间和日期）======================
2019-04-08 22:47:56,680 APIRunner.py 143 ERROR  用例（ID:2 名称：ID2-N_获取时间和日期）运行出错：步骤(第 1 步, 步骤ID: 1)运行失败:[Errno 22] Invalid argument
2019-04-08 22:47:56,689 logWebsocketConsumers.py 233 ERROR  调试运行失败：用例（ID:2 名称：ID2-N_获取时间和日期）运行出错：步骤(第 1 步, 步骤ID: 1)运行失败:[Errno 22] Invalid argument
2019-04-08 22:49:43,554 test_case_step.py 306 ERROR  [Errno 22] Invalid argument
2019-04-08 22:49:46,561 test_case.py 121 ERROR  执行用例测试步骤失败，正在进行第 1 次重试（第 1 步, 步骤ID: 1, 用例ID：2, 用例名称：ID2-N_获取时间和日期）
2019-04-08 22:49:47,747 test_case_step.py 306 ERROR  [Errno 22] Invalid argument
2019-04-08 22:49:47,755 test_case.py 131 ERROR  执行用例测试步骤运行失败（第 1 步, 步骤ID: 1， 用例ID：2, 用例名称：ID2-N_获取时间和日期）======================
2019-04-08 22:49:47,758 APIRunner.py 143 ERROR  用例（ID:2 名称：ID2-N_获取时间和日期）运行出错：步骤(第 1 步, 步骤ID: 1)运行失败:[Errno 22] Invalid argument
2019-04-08 22:49:47,770 logWebsocketConsumers.py 233 ERROR  调试运行失败：用例（ID:2 名称：ID2-N_获取时间和日期）运行出错：步骤(第 1 步, 步骤ID: 1)运行失败:[Errno 22] Invalid argument
2019-04-08 22:53:39,084 test_case_step.py 308 ERROR  [Errno 22] Invalid argument
2019-04-08 22:53:42,091 test_case.py 121 ERROR  执行用例测试步骤失败，正在进行第 1 次重试（第 1 步, 步骤ID: 1, 用例ID：2, 用例名称：ID2-N_获取时间和日期）
2019-04-08 22:53:43,220 test_case_step.py 308 ERROR  [Errno 22] Invalid argument
2019-04-08 22:53:43,228 test_case.py 131 ERROR  执行用例测试步骤运行失败（第 1 步, 步骤ID: 1， 用例ID：2, 用例名称：ID2-N_获取时间和日期）======================
2019-04-08 22:53:43,230 APIRunner.py 143 ERROR  用例（ID:2 名称：ID2-N_获取时间和日期）运行出错：步骤(第 1 步, 步骤ID: 1)运行失败:[Errno 22] Invalid argument
2019-04-08 22:53:43,243 logWebsocketConsumers.py 233 ERROR  调试运行失败：用例（ID:2 名称：ID2-N_获取时间和日期）运行出错：步骤(第 1 步, 步骤ID: 1)运行失败:[Errno 22] Invalid argument
2019-04-08 22:58:48,468 test_case.py 121 ERROR  执行用例测试步骤失败，正在进行第 1 次重试（第 1 步, 步骤ID: 2, 用例ID：4, 用例名称：ID4-N_获取时间和日期）
2019-04-08 22:58:48,497 test_case.py 131 ERROR  执行用例测试步骤运行失败（第 1 步, 步骤ID: 2， 用例ID：4, 用例名称：ID4-N_获取时间和日期）======================
2019-04-08 22:58:48,499 APIRunner.py 143 ERROR  用例（ID:4 名称：ID4-N_获取时间和日期）运行出错：步骤(第 1 步, 步骤ID: 2)运行失败:Traceback (most recent call last):
  File "D:\Program Files (x86)\python35\lib\urllib\parse.py", line 792, in urlencode
    raise TypeError
TypeError

During handling of the above exception, another exception occurred:

Traceback (most recent call last):
  File ".\website\apiRunner\interface\APIUnittestTestCase.py", line 176, in test_api_for_json
    self.input_params = urllib.parse.urlencode(self.input_params)
  File "D:\Program Files (x86)\python35\lib\urllib\parse.py", line 800, in urlencode
    "or mapping object").with_traceback(tb)
  File "D:\Program Files (x86)\python35\lib\urllib\parse.py", line 792, in urlencode
    raise TypeError
TypeError: not a valid non-string sequence or mapping object

2019-04-08 22:58:48,509 logWebsocketConsumers.py 233 ERROR  调试运行失败：用例（ID:4 名称：ID4-N_获取时间和日期）运行出错：步骤(第 1 步, 步骤ID: 2)运行失败:Traceback (most recent call last):
  File "D:\Program Files (x86)\python35\lib\urllib\parse.py", line 792, in urlencode
    raise TypeError
TypeError

During handling of the above exception, another exception occurred:

Traceback (most recent call last):
  File ".\website\apiRunner\interface\APIUnittestTestCase.py", line 176, in test_api_for_json
    self.input_params = urllib.parse.urlencode(self.input_params)
  File "D:\Program Files (x86)\python35\lib\urllib\parse.py", line 800, in urlencode
    "or mapping object").with_traceback(tb)
  File "D:\Program Files (x86)\python35\lib\urllib\parse.py", line 792, in urlencode
    raise TypeError
TypeError: not a valid non-string sequence or mapping object

2019-04-08 23:00:41,201 test_case.py 121 ERROR  执行用例测试步骤失败，正在进行第 1 次重试（第 1 步, 步骤ID: 2, 用例ID：4, 用例名称：ID4-N_获取时间和日期）
2019-04-08 23:00:41,212 test_case.py 131 ERROR  执行用例测试步骤运行失败（第 1 步, 步骤ID: 2， 用例ID：4, 用例名称：ID4-N_获取时间和日期）======================
2019-04-08 23:00:41,213 APIRunner.py 143 ERROR  用例（ID:4 名称：ID4-N_获取时间和日期）运行出错：步骤(第 1 步, 步骤ID: 2)运行失败:Traceback (most recent call last):
  File "D:\Program Files (x86)\python35\lib\urllib\parse.py", line 792, in urlencode
    raise TypeError
TypeError

During handling of the above exception, another exception occurred:

Traceback (most recent call last):
  File ".\website\apiRunner\interface\APIUnittestTestCase.py", line 176, in test_api_for_json
    self.input_params = urllib.parse.urlencode(self.input_params)
  File "D:\Program Files (x86)\python35\lib\urllib\parse.py", line 800, in urlencode
    "or mapping object").with_traceback(tb)
  File "D:\Program Files (x86)\python35\lib\urllib\parse.py", line 792, in urlencode
    raise TypeError
TypeError: not a valid non-string sequence or mapping object

2019-04-08 23:00:41,217 logWebsocketConsumers.py 233 ERROR  调试运行失败：用例（ID:4 名称：ID4-N_获取时间和日期）运行出错：步骤(第 1 步, 步骤ID: 2)运行失败:Traceback (most recent call last):
  File "D:\Program Files (x86)\python35\lib\urllib\parse.py", line 792, in urlencode
    raise TypeError
TypeError

During handling of the above exception, another exception occurred:

Traceback (most recent call last):
  File ".\website\apiRunner\interface\APIUnittestTestCase.py", line 176, in test_api_for_json
    self.input_params = urllib.parse.urlencode(self.input_params)
  File "D:\Program Files (x86)\python35\lib\urllib\parse.py", line 800, in urlencode
    "or mapping object").with_traceback(tb)
  File "D:\Program Files (x86)\python35\lib\urllib\parse.py", line 792, in urlencode
    raise TypeError
TypeError: not a valid non-string sequence or mapping object

2019-04-08 23:04:54,532 test_case.py 121 ERROR  执行用例测试步骤失败，正在进行第 1 次重试（第 1 步, 步骤ID: 2, 用例ID：4, 用例名称：ID4-N_获取时间和日期）
2019-04-08 23:04:54,559 test_case.py 131 ERROR  执行用例测试步骤运行失败（第 1 步, 步骤ID: 2， 用例ID：4, 用例名称：ID4-N_获取时间和日期）======================
2019-04-08 23:04:54,564 APIRunner.py 143 ERROR  用例（ID:4 名称：ID4-N_获取时间和日期）运行出错：步骤(第 1 步, 步骤ID: 2)运行失败:Traceback (most recent call last):
  File "D:\Program Files (x86)\python35\lib\urllib\parse.py", line 792, in urlencode
    raise TypeError
TypeError

During handling of the above exception, another exception occurred:

Traceback (most recent call last):
  File ".\website\apiRunner\interface\APIUnittestTestCase.py", line 176, in test_api_for_json
    self.input_params = urllib.parse.urlencode(self.input_params)
  File "D:\Program Files (x86)\python35\lib\urllib\parse.py", line 800, in urlencode
    "or mapping object").with_traceback(tb)
  File "D:\Program Files (x86)\python35\lib\urllib\parse.py", line 792, in urlencode
    raise TypeError
TypeError: not a valid non-string sequence or mapping object

2019-04-08 23:04:54,574 logWebsocketConsumers.py 233 ERROR  调试运行失败：用例（ID:4 名称：ID4-N_获取时间和日期）运行出错：步骤(第 1 步, 步骤ID: 2)运行失败:Traceback (most recent call last):
  File "D:\Program Files (x86)\python35\lib\urllib\parse.py", line 792, in urlencode
    raise TypeError
TypeError

During handling of the above exception, another exception occurred:

Traceback (most recent call last):
  File ".\website\apiRunner\interface\APIUnittestTestCase.py", line 176, in test_api_for_json
    self.input_params = urllib.parse.urlencode(self.input_params)
  File "D:\Program Files (x86)\python35\lib\urllib\parse.py", line 800, in urlencode
    "or mapping object").with_traceback(tb)
  File "D:\Program Files (x86)\python35\lib\urllib\parse.py", line 792, in urlencode
    raise TypeError
TypeError: not a valid non-string sequence or mapping object

2019-04-09 21:30:57,416 test_case.py 121 ERROR  执行用例测试步骤失败，正在进行第 1 次重试（第 1 步, 步骤ID: 2, 用例ID：4, 用例名称：ID4-N_获取时间和日期）
2019-04-09 21:30:57,453 test_case.py 131 ERROR  执行用例测试步骤运行失败（第 1 步, 步骤ID: 2， 用例ID：4, 用例名称：ID4-N_获取时间和日期）======================
2019-04-09 21:30:57,455 APIRunner.py 143 ERROR  用例（ID:4 名称：ID4-N_获取时间和日期）运行出错：步骤(第 1 步, 步骤ID: 2)运行失败:Traceback (most recent call last):
  File "D:\Program Files (x86)\python35\lib\urllib\parse.py", line 792, in urlencode
    raise TypeError
TypeError

During handling of the above exception, another exception occurred:

Traceback (most recent call last):
  File ".\website\apiRunner\interface\APIUnittestTestCase.py", line 176, in test_api_for_json
    self.input_params = urllib.parse.urlencode(self.input_params)
  File "D:\Program Files (x86)\python35\lib\urllib\parse.py", line 800, in urlencode
    "or mapping object").with_traceback(tb)
  File "D:\Program Files (x86)\python35\lib\urllib\parse.py", line 792, in urlencode
    raise TypeError
TypeError: not a valid non-string sequence or mapping object

2019-04-09 21:30:57,461 logWebsocketConsumers.py 233 ERROR  调试运行失败：用例（ID:4 名称：ID4-N_获取时间和日期）运行出错：步骤(第 1 步, 步骤ID: 2)运行失败:Traceback (most recent call last):
  File "D:\Program Files (x86)\python35\lib\urllib\parse.py", line 792, in urlencode
    raise TypeError
TypeError

During handling of the above exception, another exception occurred:

Traceback (most recent call last):
  File ".\website\apiRunner\interface\APIUnittestTestCase.py", line 176, in test_api_for_json
    self.input_params = urllib.parse.urlencode(self.input_params)
  File "D:\Program Files (x86)\python35\lib\urllib\parse.py", line 800, in urlencode
    "or mapping object").with_traceback(tb)
  File "D:\Program Files (x86)\python35\lib\urllib\parse.py", line 792, in urlencode
    raise TypeError
TypeError: not a valid non-string sequence or mapping object

2019-04-09 21:31:04,361 test_plan.py 92 WARNING  未查找到同测试计划关联的用例
2019-04-09 21:31:14,010 test_case.py 121 ERROR  执行用例测试步骤失败，正在进行第 1 次重试（第 1 步, 步骤ID: 2, 用例ID：4, 用例名称：ID4-N_获取时间和日期）
2019-04-09 21:31:14,047 test_case.py 131 ERROR  执行用例测试步骤运行失败（第 1 步, 步骤ID: 2， 用例ID：4, 用例名称：ID4-N_获取时间和日期）======================
2019-04-09 21:31:14,057 logWebsocketConsumers.py 260 ERROR  调试运行失败：调试运行失败：存在运行失败、被阻塞的用例：['ID4-N_获取时间和日期(ID:4),']
2019-04-09 21:31:40,049 test_case.py 121 ERROR  执行用例测试步骤失败，正在进行第 1 次重试（第 1 步, 步骤ID: 2, 用例ID：4, 用例名称：ID4-N_获取时间和日期）
2019-04-09 21:31:40,118 test_case.py 131 ERROR  执行用例测试步骤运行失败（第 1 步, 步骤ID: 2， 用例ID：4, 用例名称：ID4-N_获取时间和日期）======================
2019-04-09 21:31:40,223 APIRunner.py 353 ERROR  项目运行失败：计划ID：1，失败原因：存在运行失败、被阻塞的用例：['ID4-N_获取时间和日期(ID:4),']   
2019-04-09 21:31:40,319 logWebsocketConsumers.py 288 ERROR  在线运行失败：项目运行失败：计划ID：1，失败原因：存在运行失败、被阻塞的用例：['ID4-N_获取时间和日期(ID:4),']   
2019-04-09 21:43:06,586 test_case.py 121 ERROR  执行用例测试步骤失败，正在进行第 1 次重试（第 1 步, 步骤ID: 2, 用例ID：4, 用例名称：ID4-N_获取时间和日期）
2019-04-09 21:43:06,661 test_case.py 131 ERROR  执行用例测试步骤运行失败（第 1 步, 步骤ID: 2， 用例ID：4, 用例名称：ID4-N_获取时间和日期）======================
2019-04-09 21:43:06,766 APIRunner.py 353 ERROR  项目运行失败：计划ID：1，失败原因：存在运行失败、被阻塞的用例：['ID4-N_获取时间和日期(ID:4),']   
2019-04-09 21:43:06,798 logWebsocketConsumers.py 288 ERROR  在线运行失败：项目运行失败：计划ID：1，失败原因：存在运行失败、被阻塞的用例：['ID4-N_获取时间和日期(ID:4),']   
2019-04-09 21:44:55,561 test_case.py 121 ERROR  执行用例测试步骤失败，正在进行第 1 次重试（第 1 步, 步骤ID: 2, 用例ID：4, 用例名称：ID4-N_获取时间和日期）
2019-04-09 21:44:55,701 test_case.py 131 ERROR  执行用例测试步骤运行失败（第 1 步, 步骤ID: 2， 用例ID：4, 用例名称：ID4-N_获取时间和日期）======================
2019-04-09 21:44:55,848 APIRunner.py 353 ERROR  项目运行失败：计划ID：1，失败原因：存在运行失败、被阻塞的用例：['ID4-N_获取时间和日期(ID:4),']   
2019-04-09 21:44:55,894 logWebsocketConsumers.py 288 ERROR  在线运行失败：项目运行失败：计划ID：1，失败原因：存在运行失败、被阻塞的用例：['ID4-N_获取时间和日期(ID:4),']   
2023-06-07 16:16:36,703 running_plan_manager_views.py 217 ERROR  execute running plan fail
2023-06-07 16:18:24,345 running_plan_manager_views.py 217 ERROR  execute running plan fail
2023-06-07 16:34:12,783 running_plan_manager_views.py 217 ERROR  execute running plan fail
2023-06-07 16:38:15,706 running_plan_manager_views.py 217 ERROR  execute running plan fail
2023-06-07 16:41:04,281 running_plan_manager_views.py 217 ERROR  execute running plan fail
2023-06-07 16:42:50,483 running_plan_manager_views.py 217 ERROR  execute running plan fail
2023-06-07 16:49:57,204 running_plan_manager_views.py 217 ERROR  execute running plan fail
2023-06-09 13:57:51,152 test_case_manager_views.py 851 ERROR  name 'undefined' is not defined
2023-06-09 14:06:28,043 running_plan_manager_views.py 217 ERROR  execute running plan fail
